<?xml version="1.0" ?>
<!-- =================================================================================== -->
<!-- |    This document was autogenerated by xacro from /home/hzy/CC3/src/husky_ur3_simulator/husky_ur3_gazebo/urdf/husky_ur3_gripper.urdf.xacro | -->
<!-- |    EDITING THIS FILE BY HAND IS NOT RECOMMENDED                                 | -->
<!-- =================================================================================== -->
<!--
Software License Agreement (BSD)

\file      husky.urdf.xacro
\authors   Paul Bovbel <pbovbel@clearpathrobotics.com>, Devon Ash <dash@clearpathrobotics.com>
\copyright Copyright (c) 2015, Clearpath Robotics, Inc., All rights reserved.

Redistribution and use in source and binary forms, with or without modification, are permitted provided that
the following conditions are met:
 * Redistributions of source code must retain the above copyright notice, this list of conditions and the
   following disclaimer.
 * Redistributions in binary form must reproduce the above copyright notice, this list of conditions and the
   following disclaimer in the documentation and/or other materials provided with the distribution.
 * Neither the name of Clearpath Robotics nor the names of its contributors may be used to endorse or promote
   products derived from this software without specific prior written permission.

THIS SOFTWARE IS PROVIDED BY THE COPYRIGHT HOLDERS AND CONTRIBUTORS "AS IS" AND ANY EXPRESS OR IMPLIED WAR-
RANTIES, INCLUDING, BUT NOT LIMITED TO, THE IMPLIED WARRANTIES OF MERCHANTABILITY AND FITNESS FOR A PARTICULAR
PURPOSE ARE DISCLAIMED. IN NO EVENT SHALL THE COPYRIGHT HOLDER OR CONTRIBUTORS BE LIABLE FOR ANY DIRECT, IN-
DIRECT, INCIDENTAL, SPECIAL, EXEMPLARY, OR CONSEQUENTIAL DAMAGES (INCLUDING, BUT NOT LIMITED TO, PROCUREMENT
OF SUBSTITUTE GOODS OR SERVICES; LOSS OF USE, DATA, OR PROFITS; OR BUSINESS INTERRUPTION) HOWEVER CAUSED AND
ON ANY THEORY OF LIABILITY, WHETHER IN CONTRACT, STRICT LIABILITY, OR TORT (INCLUDING NEGLIGENCE OR OTHERWISE)
ARISING IN ANY WAY OUT OF THE USE OF THIS SOFTWARE, EVEN IF ADVISED OF THE POSSIBILITY OF SUCH DAMAGE.
-->
<robot name="husky">
    <!-- common stuff -->
    <!--xacro:include filename="$(find ur_description)/urdf/common.gazebo.xacro" /-->
    <!--
  Author: Felix Messmer
-->
    <!-- 210927 YSW: Added hardware interface and modified type of joints -->
    <!-- ros_control plugin -->
    <!--gazebo>
    <plugin name="gazebo_ros_control" filename="libgazebo_ros_control.so">
      <robotNamespace>/rh_p12_rn</robotNamespace>
      <robotSimType>gazebo_ros_control/DefaultRobotHWSim</robotSimType>
      <legacyModeNS>true</legacyModeNS>
    </plugin>
  </gazebo-->
    <!-- rh_p12_rn_base -->
    <gazebo reference="rh_p12_rn_base">
        <mu1>0.2</mu1>
        <mu2>0.2</mu2>
        <material>Gazebo/DarkGrey</material>
        <minDepth>0.001</minDepth>
        <maxVel>0</maxVel>
        <plugin name="gazebo_ros_control">
            <robotNamespace>/</robotNamespace>
        </plugin>
    </gazebo>
    <!-- rh_p12_rn_r1 -->
    <gazebo reference="rh_p12_rn_r1">
        <mu1>15</mu1>
        <mu2>150</mu2>
        <material>Gazebo/DarkGrey</material>
        <minDepth>0.001</minDepth>
        <maxVel>0</maxVel>
    </gazebo>
    <!-- rh_p12_rn_r2 -->
    <gazebo reference="rh_p12_rn_r2">
        <mu1>15</mu1>
        <mu2>150</mu2>
        <material>Gazebo/DarkGrey</material>
        <minDepth>0.001</minDepth>
        <maxVel>0</maxVel>
    </gazebo>
    <!-- rh_p12_rn_l1 -->
    <gazebo reference="rh_p12_rn_l1">
        <mu1>15</mu1>
        <mu2>150</mu2>
        <material>Gazebo/DarkGrey</material>
        <minDepth>0.001</minDepth>
        <maxVel>0</maxVel>
    </gazebo>
    <!-- rh_p12_rn_l2 -->
    <gazebo reference="rh_p12_rn_l2">
        <mu1>15</mu1>
        <mu2>150</mu2>
        <material>Gazebo/DarkGrey</material>
        <minDepth>0.001</minDepth>
        <maxVel>0</maxVel>
    </gazebo>
    <material name="black">
        <color rgba="0.0 0.0 0.0 1.0" />
    </material>
    <material name="blue">
        <color rgba="0.0 0.0 0.8 1.0" />
    </material>
    <material name="green">
        <color rgba="0.0 0.8 0.0 1.0" />
    </material>
    <material name="grey">
        <color rgba="0.2 0.2 0.2 1.0" />
    </material>
    <material name="orange">
        <color rgba="1.0 0.4235294117647059 0.0392156862745098 1.0" />
    </material>
    <material name="brown">
        <color rgba="0.8705882352941177 0.8117647058823529 0.7647058823529411 1.0" />
    </material>
    <material name="red">
        <color rgba="0.8 0.0 0.0 1.0" />
    </material>
    <material name="white">
        <color rgba="1.0 1.0 1.0 1.0" />
    </material>
    <!-- base -->
    <link name="rh_p12_rn_base">
        <collision>
            <origin rpy="0 0 0" xyz="0 0 0" />
            <geometry>
                <mesh filename="package://husky_ur3_gazebo/meshes/base.stl" scale="0.001 0.001 0.001" />
            </geometry>
        </collision>
        <visual>
            <origin rpy="0 0 0" xyz="0 0 0" />
            <geometry>
                <mesh filename="package://husky_ur3_gazebo/meshes/base.stl" scale="0.001 0.001 0.001" />
            </geometry>
            <material name="grey" />
        </visual>
        <inertial>
            <origin rpy="0 0 0" xyz="0.000 0.000 0.032" />
            <mass value="0.236" />
            <!--<inertia ixx="0.00017" ixy="0.0" ixz="0.0" iyy="0.00011" iyz="0.0" izz="0.00017" />-->
            <inertia ixx="1.0" ixy="0.0" ixz="0.0" iyy="1.0" iyz="0.0" izz="1.0" />
        </inertial>
    </link>
    <!-- Joint -->
    <joint name="rh_p12_rn" type="revolute">
        <parent link="rh_p12_rn_base" />
        <child link="rh_p12_rn_r1" />
        <origin rpy="0 0 0" xyz="0.0 0.008 0.048" />
        <axis xyz="1 0 0" />
        <limit effort="1000" lower="0.0" upper="1.1" velocity="6.5" />
        <dynamics damping="0.7" />
    </joint>
    <transmission name="tran_r1">
        <type>transmission_interface/SimpleTransmission</type>
        <joint name="rh_p12_rn">
            <hardwareInterface>hardware_interface/EffortJointInterface</hardwareInterface>
        </joint>
        <actuator name="motor_r1">
            <hardwareInterface>hardware_interface/EffortJointInterface</hardwareInterface>
            <mechanicalReduction>1</mechanicalReduction>
        </actuator>
    </transmission>
    <!-- rh_p12_rn_r1 -->
    <link name="rh_p12_rn_r1">
        <collision>
            <origin rpy="0 0 0" xyz="0 0 0" />
            <geometry>
                <mesh filename="package://husky_ur3_gazebo/meshes/r1.stl" scale="0.001 0.001 0.001" />
            </geometry>
        </collision>
        <visual>
            <origin rpy="0 0 0" xyz="0 0 0" />
            <geometry>
                <mesh filename="package://husky_ur3_gazebo/meshes/r1.stl" scale="0.001 0.001 0.001" />
            </geometry>
            <material name="grey" />
        </visual>
        <inertial>
            <origin rpy="0 0 0" xyz="0.000 0.034 0.004" />
            <mass value="0.068" />
            <!--<inertia ixx="0.00004" ixy="0.0" ixz="0.0" iyy="0.00002" iyz="-0.00001" izz="0.00002" />-->
            <inertia ixx="1.0" ixy="0.0" ixz="0.0" iyy="1.0" iyz="0.0" izz="1.0" />
        </inertial>
    </link>
    <!-- Right Joint 2 -->
    <joint name="rh_r2" type="revolute">
        <parent link="rh_p12_rn_r1" />
        <child link="rh_p12_rn_r2" />
        <origin rpy="0 0 0" xyz="0.0 0.0493634 0.0285" />
        <axis xyz="-1 0 0" />
        <limit effort="1000" lower="0.0" upper="1.0" velocity="6.5" />
        <dynamics damping="0.7" />
    </joint>
    <transmission name="tran_r2">
        <type>transmission_interface/SimpleTransmission</type>
        <joint name="rh_r2">
            <hardwareInterface>hardware_interface/EffortJointInterface</hardwareInterface>
        </joint>
        <actuator name="motor_r2">
            <hardwareInterface>hardware_interface/EffortJointInterface</hardwareInterface>
            <mechanicalReduction>1</mechanicalReduction>
        </actuator>
    </transmission>
    <!-- rh_p12_rn_r2 -->
    <link name="rh_p12_rn_r2">
        <collision>
            <origin rpy="0 0 0" xyz="0 0 0" />
            <geometry>
                <mesh filename="package://husky_ur3_gazebo/meshes/r2.stl" scale="0.001 0.001 0.001" />
            </geometry>
        </collision>
        <visual>
            <origin rpy="0 0 0" xyz="0 0 0" />
            <geometry>
                <mesh filename="package://husky_ur3_gazebo/meshes/r2.stl" scale="0.001 0.001 0.001" />
            </geometry>
            <material name="grey" />
        </visual>
        <inertial>
            <origin rpy="0 0 0" xyz="0.000 0.006 0.011" />
            <mass value="0.022" />
            <!--<inertia ixx="0.0" ixy="0.0" ixz="0.0" iyy="0.00001" iyz="0.0" izz="0.0" />-->
            <inertia ixx="1.0" ixy="0.0" ixz="0.0" iyy="1.0" iyz="0.0" izz="1.0" />
        </inertial>
    </link>
    <!-- Left Joint 1 -->
    <joint name="rh_l1" type="revolute">
        <parent link="rh_p12_rn_base" />
        <child link="rh_p12_rn_l1" />
        <origin rpy="0 0 0" xyz="0.0 -0.008 0.048" />
        <axis xyz="-1 0 0" />
        <limit effort="1000" lower="0.0" upper="1.1" velocity="6.5" />
        <dynamics damping="0.7" />
    </joint>
    <transmission name="tran_l1">
        <type>transmission_interface/SimpleTransmission</type>
        <joint name="rh_l1">
            <hardwareInterface>hardware_interface/EffortJointInterface</hardwareInterface>
        </joint>
        <actuator name="motor_l1">
            <hardwareInterface>hardware_interface/EffortJointInterface</hardwareInterface>
            <mechanicalReduction>1</mechanicalReduction>
        </actuator>
    </transmission>
    <!-- rh_p12_rn_l1 -->
    <link name="rh_p12_rn_l1">
        <collision>
            <origin rpy="0 0 0" xyz="0 0 0" />
            <geometry>
                <mesh filename="package://husky_ur3_gazebo/meshes/l1.stl" scale="0.001 0.001 0.001" />
            </geometry>
        </collision>
        <visual>
            <origin rpy="0 0 0" xyz="0 0 0" />
            <geometry>
                <mesh filename="package://husky_ur3_gazebo/meshes/l1.stl" scale="0.001 0.001 0.001" />
            </geometry>
            <material name="grey" />
        </visual>
        <inertial>
            <origin rpy="0 0 0" xyz="0.000 -0.034 0.004" />
            <mass value="0.068" />
            <!--<inertia ixx="0.00004" ixy="0.0" ixz="0.0" iyy="0.00002" iyz="0.00001" izz="0.00002" />-->
            <inertia ixx="1.0" ixy="0.0" ixz="0.0" iyy="1.0" iyz="0.0" izz="1.0" />
        </inertial>
    </link>
    <!-- Left Joint 2 -->
    <joint name="rh_l2" type="revolute">
        <parent link="rh_p12_rn_l1" />
        <child link="rh_p12_rn_l2" />
        <origin rpy="0 0 0" xyz="0.0 -0.0493634 0.0285" />
        <axis xyz="1 0 0" />
        <limit effort="1000" lower="0.0" upper="1.0" velocity="6.5" />
        <dynamics damping="0.7" />
    </joint>
    <transmission name="tran_l2">
        <type>transmission_interface/SimpleTransmission</type>
        <joint name="rh_l2">
            <hardwareInterface>hardware_interface/EffortJointInterface</hardwareInterface>
        </joint>
        <actuator name="motor_l2">
            <hardwareInterface>hardware_interface/EffortJointInterface</hardwareInterface>
            <mechanicalReduction>1</mechanicalReduction>
        </actuator>
    </transmission>
    <!-- rh_p12_rn_l2 -->
    <link name="rh_p12_rn_l2">
        <collision>
            <origin rpy="0 0 0" xyz="0 0 0" />
            <geometry>
                <mesh filename="package://husky_ur3_gazebo/meshes/l2.stl" scale="0.001 0.001 0.001" />
            </geometry>
        </collision>
        <visual>
            <origin rpy="0 0 0" xyz="0 0 0" />
            <geometry>
                <mesh filename="package://husky_ur3_gazebo/meshes/l2.stl" scale="0.001 0.001 0.001" />
            </geometry>
            <material name="grey" />
        </visual>
        <inertial>
            <origin rpy="0 0 0" xyz="0.000 -0.006 0.011" />
            <mass value="0.022" />
            <!--<inertia ixx="0.0" ixy="0.0" ixz="0.0" iyy="0.00001" iyz="0.0" izz="0.0" />-->
            <inertia ixx="1.0" ixy="0.0" ixz="0.0" iyy="1.0" iyz="0.0" izz="1.0" />
        </inertial>
    </link>
    <!-- measured from model -->
    <link name="ur3_base_link">
        <visual>
            <geometry>
                <mesh filename="package://husky_ur3_gazebo/meshes/ur3/visual/base.dae" />
            </geometry>
            <material name="LightGrey">
                <color rgba="0.7 0.7 0.7 1.0" />
            </material>
        </visual>
        <collision>
            <geometry>
                <mesh filename="package://husky_ur3_gazebo/meshes/ur3/collision/base.stl" />
            </geometry>
        </collision>
        <inertial>
            <mass value="2.0" />
            <origin rpy="0 0 0" xyz="0.0 0.0 0.0" />
            <inertia ixx="0.0030531654454" ixy="0.0" ixz="0.0" iyy="0.0030531654454" iyz="0.0" izz="0.005625" />
        </inertial>
    </link>
    <joint name="shoulder_pan_joint" type="revolute">
        <parent link="ur3_base_link" />
        <child link="shoulder_link" />
        <origin rpy="0.0 0.0 0.0" xyz="0.0 0.0 0.1519" />
        <axis xyz="0 0 1" />
        <limit effort="330.0" lower="-3.141592654" upper="3.141592654" velocity="2.16" />
        <dynamics damping="0.0" friction="0.0" />
    </joint>
    <link name="shoulder_link">
        <visual>
            <geometry>
                <mesh filename="package://husky_ur3_gazebo/meshes/ur3/visual/shoulder.dae" />
            </geometry>
            <material name="LightGrey">
                <color rgba="0.7 0.7 0.7 1.0" />
            </material>
        </visual>
        <collision>
            <geometry>
                <mesh filename="package://husky_ur3_gazebo/meshes/ur3/collision/shoulder.stl" />
            </geometry>
        </collision>
        <inertial>
            <mass value="2.0" />
            <origin rpy="0 0 0" xyz="0.0 0.0 0.0" />
            <inertia ixx="0.008093163429399999" ixy="0.0" ixz="0.0" iyy="0.008093163429399999" iyz="0.0" izz="0.005625" />
        </inertial>
    </link>
    <joint name="shoulder_lift_joint" type="revolute">
        <parent link="shoulder_link" />
        <child link="upper_arm_link" />
        <origin rpy="0.0 1.570796327 0.0" xyz="0.0 0.1198 0.0" />
        <axis xyz="0 1 0" />
        <limit effort="330.0" lower="-3.141592654" upper="3.141592654" velocity="2.16" />
        <dynamics damping="0.0" friction="0.0" />
    </joint>
    <link name="upper_arm_link">
        <visual>
            <geometry>
                <mesh filename="package://husky_ur3_gazebo/meshes/ur3/visual/upperarm.dae" />
            </geometry>
            <material name="LightGrey">
                <color rgba="0.7 0.7 0.7 1.0" />
            </material>
        </visual>
        <collision>
            <geometry>
                <mesh filename="package://husky_ur3_gazebo/meshes/ur3/collision/upperarm.stl" />
            </geometry>
        </collision>
        <inertial>
            <mass value="3.42" />
            <origin rpy="0 0 0" xyz="0.0 0.0 0.121825" />
            <inertia ixx="0.021728483221103233" ixy="0.0" ixz="0.0" iyy="0.021728483221103233" iyz="0.0" izz="0.00961875" />
        </inertial>
    </link>
    <joint name="elbow_joint" type="revolute">
        <parent link="upper_arm_link" />
        <child link="forearm_link" />
        <origin rpy="0.0 0.0 0.0" xyz="0.0 -0.0925 0.24365" />
        <axis xyz="0 1 0" />
        <limit effort="150.0" lower="-2.618002654" upper="3.141592654" velocity="3.15" />
        <dynamics damping="0.0" friction="0.0" />
    </joint>
    <link name="forearm_link">
        <visual>
            <geometry>
                <mesh filename="package://husky_ur3_gazebo/meshes/ur3/visual/forearm.dae" />
            </geometry>
            <material name="LightGrey">
                <color rgba="0.7 0.7 0.7 1.0" />
            </material>
        </visual>
        <collision>
            <geometry>
                <mesh filename="package://husky_ur3_gazebo/meshes/ur3/collision/forearm.stl" />
            </geometry>
        </collision>
        <inertial>
            <mass value="1.26" />
            <origin rpy="0 0 0" xyz="0.0 0.0 0.106625" />
            <inertia ixx="0.006546806443776375" ixy="0.0" ixz="0.0" iyy="0.006546806443776375" iyz="0.0" izz="0.00354375" />
        </inertial>
    </link>
    <joint name="wrist_1_joint" type="revolute">
        <parent link="forearm_link" />
        <child link="wrist_1_link" />
        <origin rpy="0.0 1.570796327 0.0" xyz="0.0 0.0 0.21325" />
        <axis xyz="0 1 0" />
        <limit effort="54.0" lower="-3.141592654" upper="3.141592654" velocity="3.2" />
        <dynamics damping="0.0" friction="0.0" />
    </joint>
    <link name="wrist_1_link">
        <visual>
            <geometry>
                <mesh filename="package://husky_ur3_gazebo/meshes/ur3/visual/wrist1.dae" />
            </geometry>
            <material name="LightGrey">
                <color rgba="0.7 0.7 0.7 1.0" />
            </material>
        </visual>
        <collision>
            <geometry>
                <mesh filename="package://husky_ur3_gazebo/meshes/ur3/collision/wrist1.stl" />
            </geometry>
        </collision>
        <inertial>
            <mass value="0.8" />
            <origin rpy="0 0 0" xyz="0.0 0.08505 0.0" />
            <inertia ixx="0.002084999166" ixy="0.0" ixz="0.0" iyy="0.002084999166" iyz="0.0" izz="0.00225" />
        </inertial>
    </link>
    <joint name="wrist_2_joint" type="revolute">
        <parent link="wrist_1_link" />
        <child link="wrist_2_link" />
        <origin rpy="0.0 0.0 0.0" xyz="0.0 0.08505 0.0" />
        <axis xyz="0 0 1" />
        <limit effort="54.0" lower="-3.141592654" upper="3.141592654" velocity="3.2" />
        <dynamics damping="0.0" friction="0.0" />
    </joint>
    <link name="wrist_2_link">
        <visual>
            <geometry>
                <mesh filename="package://husky_ur3_gazebo/meshes/ur3/visual/wrist2.dae" />
            </geometry>
            <material name="LightGrey">
                <color rgba="0.7 0.7 0.7 1.0" />
            </material>
        </visual>
        <collision>
            <geometry>
                <mesh filename="package://husky_ur3_gazebo/meshes/ur3/collision/wrist2.stl" />
            </geometry>
        </collision>
        <inertial>
            <mass value="0.8" />
            <origin rpy="0 0 0" xyz="0.0 0.0 0.08535" />
            <inertia ixx="0.002084999166" ixy="0.0" ixz="0.0" iyy="0.002084999166" iyz="0.0" izz="0.00225" />
        </inertial>
    </link>
    <joint name="wrist_3_joint" type="revolute">
        <parent link="wrist_2_link" />
        <child link="wrist_3_link" />
        <origin rpy="0.0 0.0 0.0" xyz="0.0 0.0 0.08535" />
        <axis xyz="0 1 0" />
        <limit effort="54.0" lower="-3.141592654" upper="3.141592654" velocity="3.2" />
        <dynamics damping="0.0" friction="0.0" />
    </joint>
    <link name="wrist_3_link">
        <visual>
            <geometry>
                <mesh filename="package://husky_ur3_gazebo/meshes/ur3/visual/wrist3.dae" />
            </geometry>
            <material name="LightGrey">
                <color rgba="0.7 0.7 0.7 1.0" />
            </material>
        </visual>
        <collision>
            <geometry>
                <mesh filename="package://husky_ur3_gazebo/meshes/ur3/collision/wrist3.stl" />
            </geometry>
        </collision>
        <inertial>
            <mass value="0.35" />
            <origin rpy="1.570796327 0 0" xyz="0.0 0.0619 0.0" />
            <inertia ixx="0.00013626661215999998" ixy="0.0" ixz="0.0" iyy="0.00013626661215999998" iyz="0.0" izz="0.0001792" />
        </inertial>
    </link>
    <joint name="ee_fixed_joint" type="fixed">
        <parent link="wrist_3_link" />
        <child link="ee_link" />
        <origin rpy="0.0 0.0 1.570796327" xyz="0.0 0.0819 0.0" />
    </joint>
    <link name="ee_link">
        <collision>
            <geometry>
                <box size="0.01 0.01 0.01" />
            </geometry>
            <origin rpy="0 0 0" xyz="-0.01 0 0" />
        </collision>
        <inertial>
            <mass value="0.1" />
            <origin xyz="0 0 0" rpy="0 0 0" />
            <inertia ixx="0.03" iyy="0.03" izz="0.03" ixy="0.0" ixz="0.0" iyz="0.0" />
        </inertial>
    </link>
    <transmission name="shoulder_pan_trans">
        <type>transmission_interface/SimpleTransmission</type>
        <joint name="shoulder_pan_joint">
            <hardwareInterface>hardware_interface/PositionJointInterface</hardwareInterface>
        </joint>
        <actuator name="shoulder_pan_motor">
            <mechanicalReduction>1</mechanicalReduction>
            <hardwareInterface>hardware_interface/EffortJointInterface</hardwareInterface>
        </actuator>
    </transmission>
    <transmission name="shoulder_lift_trans">
        <type>transmission_interface/SimpleTransmission</type>
        <joint name="shoulder_lift_joint">
            <hardwareInterface>hardware_interface/PositionJointInterface</hardwareInterface>
        </joint>
        <actuator name="shoulder_lift_motor">
            <mechanicalReduction>1</mechanicalReduction>
            <hardwareInterface>hardware_interface/EffortJointInterface</hardwareInterface>
        </actuator>
    </transmission>
    <transmission name="elbow_trans">
        <type>transmission_interface/SimpleTransmission</type>
        <joint name="elbow_joint">
            <hardwareInterface>hardware_interface/PositionJointInterface</hardwareInterface>
        </joint>
        <actuator name="elbow_motor">
            <mechanicalReduction>1</mechanicalReduction>
            <hardwareInterface>hardware_interface/EffortJointInterface</hardwareInterface>
        </actuator>
    </transmission>
    <transmission name="wrist_1_trans">
        <type>transmission_interface/SimpleTransmission</type>
        <joint name="wrist_1_joint">
            <hardwareInterface>hardware_interface/PositionJointInterface</hardwareInterface>
        </joint>
        <actuator name="wrist_1_motor">
            <mechanicalReduction>1</mechanicalReduction>
            <hardwareInterface>hardware_interface/EffortJointInterface</hardwareInterface>
        </actuator>
    </transmission>
    <transmission name="wrist_2_trans">
        <type>transmission_interface/SimpleTransmission</type>
        <joint name="wrist_2_joint">
            <hardwareInterface>hardware_interface/PositionJointInterface</hardwareInterface>
        </joint>
        <actuator name="wrist_2_motor">
            <mechanicalReduction>1</mechanicalReduction>
            <hardwareInterface>hardware_interface/EffortJointInterface</hardwareInterface>
        </actuator>
    </transmission>
    <transmission name="wrist_3_trans">
        <type>transmission_interface/SimpleTransmission</type>
        <joint name="wrist_3_joint">
            <hardwareInterface>hardware_interface/PositionJointInterface</hardwareInterface>
        </joint>
        <actuator name="wrist_3_motor">
            <mechanicalReduction>1</mechanicalReduction>
            <hardwareInterface>hardware_interface/EffortJointInterface</hardwareInterface>
        </actuator>
    </transmission>
    <gazebo reference="shoulder_link">
        <selfCollide>true</selfCollide>
    </gazebo>
    <gazebo reference="upper_arm_link">
        <selfCollide>true</selfCollide>
    </gazebo>
    <gazebo reference="forearm_link">
        <selfCollide>true</selfCollide>
    </gazebo>
    <gazebo reference="wrist_1_link">
        <selfCollide>true</selfCollide>
    </gazebo>
    <gazebo reference="wrist_3_link">
        <selfCollide>true</selfCollide>
    </gazebo>
    <gazebo reference="wrist_2_link">
        <selfCollide>true</selfCollide>
    </gazebo>
    <gazebo reference="ee_link">
        <selfCollide>true</selfCollide>
    </gazebo>
    <!-- ROS ur3_base_link to UR 'Base' Coordinates transform -->
    <link name="base" />
    <joint name="ur3_base_link-base_fixed_joint" type="fixed">
        <!-- NOTE: this rotation is only needed as long as ur3_base_link itself is
                 not corrected wrt the real robot (ie: rotated over 180
                 degrees)
      -->
        <origin rpy="0 0 -3.141592654" xyz="0 0 0" />
        <parent link="ur3_base_link" />
        <child link="base" />
    </joint>
    <!-- Frame coincident with all-zeros TCP on UR controller -->
    <link name="tool0" />
    <joint name="wrist_3_link-tool0_fixed_joint" type="fixed">
        <origin rpy="-1.570796327 0 0" xyz="0 0.0819 0" />
        <parent link="wrist_3_link" />
        <child link="tool0" />
    </joint>
    <joint name="husky_ur3_joint" type="fixed">
        <parent link="top_plate_link" />
        <child link="ur3_base_link" />
        <origin rpy="0.0 0.0 -1.57" xyz="0.25 0 0.0065" />
    </joint>
    <joint name="ur3_gripper_joint" type="fixed">
        <parent link="ee_link" />
        <child link="rh_p12_rn_base" />
        <origin rpy="0 1.57 0" xyz="0 0 0" />
    </joint>
    <!-- camera body, with origin at bottom screw mount -->
    <joint name="g_camera_joint" type="fixed">
        <origin rpy="-3.141592654 0 0" xyz="0.0 0.00 -0.04" />
        <parent link="ee_link" />
        <child link="g_camera_bottom_screw_frame" />
    </joint>
    <link name="g_camera_bottom_screw_frame" />
    <joint name="g_camera_link_joint" type="fixed">
        <origin rpy="0 0 0" xyz="0.010600000000000002 0.0175 0.0125" />
        <parent link="g_camera_bottom_screw_frame" />
        <child link="g_camera_link" />
    </joint>
    <link name="g_camera_link">
        <visual>
            <!-- the mesh origin is at front plate in betw`n the two infrared camera axes -->
            <origin rpy="1.5707963267948966 0 1.5707963267948966" xyz="0.0043 -0.0175 0" />
            <geometry>
                <!-- <box size="${d435_cam_width} ${d435_cam_height} ${d435_cam_depth}"/> -->
                <mesh filename="package://realsense2_description/meshes/d435.dae" />
            </geometry>
            <material name="white">
                <color rgba="0 0 0" />
            </material>
        </visual>
        <collision>
            <origin rpy="0 0 0" xyz="0 -0.0175 0" />
            <geometry>
                <box size="0.02505 0.09 0.025" />
            </geometry>
        </collision>
        <inertial>
            <!-- The following are not reliable values, and should not be used for modeling -->
            <mass value="0.072" />
            <origin xyz="0 0 0" rpy="0 0 0" />
            <inertia ixx="0.003881243" ixy="0.0" ixz="0.0" iyy="0.000498940" iyz="0.0" izz="0.003879257" />
        </inertial>
    </link>
    <!-- camera depth joints and links -->
    <joint name="g_camera_depth_joint" type="fixed">
        <origin rpy="0 0 0" xyz="0 0 0" />
        <parent link="g_camera_link" />
        <child link="g_camera_depth_frame" />
    </joint>
    <link name="g_camera_depth_frame" />
    <joint name="g_camera_depth_optical_joint" type="fixed">
        <origin rpy="-1.5707963267948966 0 -1.5707963267948966" xyz="0 0 0" />
        <parent link="g_camera_depth_frame" />
        <child link="g_camera_depth_optical_frame" />
    </joint>
    <link name="g_camera_depth_optical_frame" />
    <!-- camera left IR joints and links -->
    <joint name="g_camera_infra1_joint" type="fixed">
        <origin rpy="0 0 0" xyz="0 0.0 0" />
        <parent link="g_camera_link" />
        <child link="g_camera_infra1_frame" />
    </joint>
    <link name="g_camera_infra1_frame" />
    <joint name="g_camera_infra1_optical_joint" type="fixed">
        <origin rpy="-1.5707963267948966 0 -1.5707963267948966" xyz="0 0 0" />
        <parent link="g_camera_infra1_frame" />
        <child link="g_camera_infra1_optical_frame" />
    </joint>
    <link name="g_camera_infra1_optical_frame" />
    <!-- camera right IR joints and links -->
    <joint name="g_camera_infra2_joint" type="fixed">
        <origin rpy="0 0 0" xyz="0 -0.05 0" />
        <parent link="g_camera_link" />
        <child link="g_camera_infra2_frame" />
    </joint>
    <link name="g_camera_infra2_frame" />
    <joint name="g_camera_infra2_optical_joint" type="fixed">
        <origin rpy="-1.5707963267948966 0 -1.5707963267948966" xyz="0 0 0" />
        <parent link="g_camera_infra2_frame" />
        <child link="g_camera_infra2_optical_frame" />
    </joint>
    <link name="g_camera_infra2_optical_frame" />
    <!-- camera color joints and links -->
    <joint name="g_camera_color_joint" type="fixed">
        <origin rpy="0 0 0" xyz="0 0.015 0" />
        <parent link="g_camera_link" />
        <child link="g_camera_color_frame" />
    </joint>
    <link name="g_camera_color_frame" />
    <joint name="g_camera_color_optical_joint" type="fixed">
        <origin rpy="-1.5707963267948966 0 -1.5707963267948966" xyz="0 0 0" />
        <parent link="g_camera_color_frame" />
        <child link="g_camera_color_optical_frame" />
    </joint>
    <link name="g_camera_color_optical_frame" />
    <!--
    <xacro:if value="$(arg add_plug)">
      <xacro:usb_plug parent="${name}_link" name="${name}_usb_plug">
        <origin xyz="${d435_cam_mount_from_center_offset - 0.02095} ${-d435_cam_depth_py - 0.0353} 0" rpy="0 0 0"/>
      </xacro:usb_plug>
    </xacro:if>-->
    <gazebo reference="g_camera_link">
        <sensor name="g_camera" type="depth">
            <always_on>1</always_on>
            <visualize>true</visualize>
            <camera>
                <horizontal_fov>1.0471975511965976</horizontal_fov>
                <image>
                    <width>640</width>
                    <height>480</height>
                    <format>R8G8B8</format>
                </image>
                <depth_camera />
                <clip>
                    <near>0.11</near>
                    <far>10</far>
                </clip>
            </camera>
            <plugin filename="libgazebo_ros_openni_kinect.so" name="g_camera_controller">
                <alwaysOn>true</alwaysOn>
                <updateRate>20.0</updateRate>
                <cameraName>g_d435</cameraName>
                <frameName>g_camera_depth_optical_frame</frameName>
                <imageTopicName>rgb/g_image_raw</imageTopicName>
                <depthImageTopicName>depth/g_image_raw</depthImageTopicName>
                <pointCloudTopicName>depth/g_points</pointCloudTopicName>
                <cameraInfoTopicName>rgb/camera_info</cameraInfoTopicName>
                <depthImageCameraInfoTopicName>depth/camera_info</depthImageCameraInfoTopicName>
                <pointCloudCutoff>0.4</pointCloudCutoff>
                <hackBaseline>0.07</hackBaseline>
                <distortionK1>0.0</distortionK1>
                <distortionK2>0.0</distortionK2>
                <distortionK3>0.0</distortionK3>
                <distortionT1>0.0</distortionT1>
                <distortionT2>0.0</distortionT2>
                <CxPrime>0.0</CxPrime>
                <Cx>0.0</Cx>
                <Cy>0.0</Cy>
                <focalLength>0.0</focalLength>
            </plugin>
        </sensor>
    </gazebo>
    - -
    <!--xacro:include filename="$(find husky_ur3_gazebo)/urdf/ur3_robot.urdf.xacro"/-->
    <!-- Base link is the center of the robot's bottom plate -->
    <link name="base_link">
        <visual>
            <origin rpy="0 0 0" xyz="0 0 0" />
            <geometry>
                <mesh filename="package://husky_ur3_gazebo/meshes/base_link.dae" />
            </geometry>
        </visual>
        <collision>
            <origin rpy="0 0 0" xyz="0.0 0 0.061875" />
            <geometry>
                <box size="0.9874 0.5709 0.12375" />
            </geometry>
        </collision>
        <collision>
            <origin rpy="0 0 0" xyz="0 0 0.17562499999999998" />
            <geometry>
                <box size="0.7899200000000001 0.5709 0.10375" />
            </geometry>
        </collision>
        <inertial>
            <mass value="0.1" />
            <origin xyz="0 0 0" rpy="0 0 0" />
            <inertia ixx="0.03" iyy="0.03" izz="0.03" ixy="0.0" ixz="0.0" iyz="0.0" />
        </inertial>
    </link>
    <!-- Base footprint is on the ground under the robot -->
    <link name="base_footprint" />
    <joint name="base_footprint_joint" type="fixed">
        <origin rpy="0 0 0" xyz="0 0 -0.13228" />
        <parent link="base_link" />
        <child link="base_footprint" />
    </joint>
    <!-- Interial link stores the robot's inertial information -->
    <link name="inertial_link">
        <inertial>
            <mass value="46.034" />
            <origin xyz="-0.00065 -0.085 0.062" />
            <inertia ixx="0.6022" ixy="-0.02364" ixz="-0.1197" iyy="1.7386" iyz="-0.001544" izz="2.0296" />
        </inertial>
    </link>
    <joint name="inertial_joint" type="fixed">
        <origin rpy="0 0 0" xyz="0 0 0" />
        <parent link="base_link" />
        <child link="inertial_link" />
    </joint>
    <!-- IMU Link is the standard mounting position for the UM6 IMU.-->
    <!-- Can be modified with environment variables in /etc/ros/setup.bash -->
    <link name="imu_link" />
    <joint name="imu_joint" type="fixed">
        <origin rpy="0 -1.5708 3.1416" xyz="0.19 0 0.149" />
        <parent link="base_link" />
        <child link="imu_link" />
    </joint>
    <gazebo reference="imu_link" />
    <link name="front_left_wheel_link">
        <inertial>
            <mass value="2.637" />
            <origin xyz="0 0 0" rpy="0 0 0" />
            <inertia ixx="0.02467" ixy="0" ixz="0" iyy="0.04411" iyz="0" izz="0.02467" />
        </inertial>
        <visual>
            <origin rpy="0 0 0" xyz="0 0 0" />
            <geometry>
                <mesh filename="package://husky_ur3_gazebo/meshes/wheel.dae" />
            </geometry>
        </visual>
        <collision>
            <origin rpy="1.570795 0 0" xyz="0 0 0" />
            <geometry>
                <cylinder length="0.1143" radius="0.1651" />
            </geometry>
        </collision>
    </link>
    <joint name="front_left_wheel" type="continuous">
        <parent link="base_link" />
        <child link="front_left_wheel_link" />
        <origin rpy="0 0 0" xyz="0.256 0.2854 0.03282" />
        <axis rpy="0 0 0" xyz="0 1 0" />
    </joint>
    <transmission name="front_left_wheel_trans" type="SimpleTransmission">
        <type>transmission_interface/SimpleTransmission</type>
        <actuator name="front_left_wheel_motor">
            <mechanicalReduction>1</mechanicalReduction>
            <hardwareInterface>hardware_interface/EffortJointInterface</hardwareInterface>
        </actuator>
        <joint name="front_left_wheel">
            <hardwareInterface>hardware_interface/VelocityJointInterface</hardwareInterface>
        </joint>
    </transmission>
    <link name="front_right_wheel_link">
        <inertial>
            <mass value="2.637" />
            <origin xyz="0 0 0" rpy="0 0 0" />
            <inertia ixx="0.02467" ixy="0" ixz="0" iyy="0.04411" iyz="0" izz="0.02467" />
        </inertial>
        <visual>
            <origin rpy="0 0 0" xyz="0 0 0" />
            <geometry>
                <mesh filename="package://husky_ur3_gazebo/meshes/wheel.dae" />
            </geometry>
        </visual>
        <collision>
            <origin rpy="1.570795 0 0" xyz="0 0 0" />
            <geometry>
                <cylinder length="0.1143" radius="0.1651" />
            </geometry>
        </collision>
    </link>
    <joint name="front_right_wheel" type="continuous">
        <parent link="base_link" />
        <child link="front_right_wheel_link" />
        <origin rpy="0 0 0" xyz="0.256 -0.2854 0.03282" />
        <axis rpy="0 0 0" xyz="0 1 0" />
    </joint>
    <transmission name="front_right_wheel_trans" type="SimpleTransmission">
        <type>transmission_interface/SimpleTransmission</type>
        <actuator name="front_right_wheel_motor">
            <mechanicalReduction>1</mechanicalReduction>
            <hardwareInterface>hardware_interface/EffortJointInterface</hardwareInterface>
        </actuator>
        <joint name="front_right_wheel">
            <hardwareInterface>hardware_interface/VelocityJointInterface</hardwareInterface>
        </joint>
    </transmission>
    <link name="rear_left_wheel_link">
        <inertial>
            <mass value="2.637" />
            <origin xyz="0 0 0" rpy="0 0 0" />
            <inertia ixx="0.02467" ixy="0" ixz="0" iyy="0.04411" iyz="0" izz="0.02467" />
        </inertial>
        <visual>
            <origin rpy="0 0 0" xyz="0 0 0" />
            <geometry>
                <mesh filename="package://husky_ur3_gazebo/meshes/wheel.dae" />
            </geometry>
        </visual>
        <collision>
            <origin rpy="1.570795 0 0" xyz="0 0 0" />
            <geometry>
                <cylinder length="0.1143" radius="0.1651" />
            </geometry>
        </collision>
    </link>
    <joint name="rear_left_wheel" type="continuous">
        <parent link="base_link" />
        <child link="rear_left_wheel_link" />
        <origin rpy="0 0 0" xyz="-0.256 0.2854 0.03282" />
        <axis rpy="0 0 0" xyz="0 1 0" />
    </joint>
    <transmission name="rear_left_wheel_trans" type="SimpleTransmission">
        <type>transmission_interface/SimpleTransmission</type>
        <actuator name="rear_left_wheel_motor">
            <mechanicalReduction>1</mechanicalReduction>
            <hardwareInterface>hardware_interface/EffortJointInterface</hardwareInterface>
        </actuator>
        <joint name="rear_left_wheel">
            <hardwareInterface>hardware_interface/VelocityJointInterface</hardwareInterface>
        </joint>
    </transmission>
    <link name="rear_right_wheel_link">
        <inertial>
            <mass value="2.637" />
            <origin xyz="0 0 0" rpy="0 0 0" />
            <inertia ixx="0.02467" ixy="0" ixz="0" iyy="0.04411" iyz="0" izz="0.02467" />
        </inertial>
        <visual>
            <origin rpy="0 0 0" xyz="0 0 0" />
            <geometry>
                <mesh filename="package://husky_ur3_gazebo/meshes/wheel.dae" />
            </geometry>
        </visual>
        <collision>
            <origin rpy="1.570795 0 0" xyz="0 0 0" />
            <geometry>
                <cylinder length="0.1143" radius="0.1651" />
            </geometry>
        </collision>
    </link>
    <joint name="rear_right_wheel" type="continuous">
        <parent link="base_link" />
        <child link="rear_right_wheel_link" />
        <origin rpy="0 0 0" xyz="-0.256 -0.2854 0.03282" />
        <axis rpy="0 0 0" xyz="0 1 0" />
    </joint>
    <transmission name="rear_right_wheel_trans" type="SimpleTransmission">
        <type>transmission_interface/SimpleTransmission</type>
        <actuator name="rear_right_wheel_motor">
            <mechanicalReduction>1</mechanicalReduction>
            <hardwareInterface>hardware_interface/EffortJointInterface</hardwareInterface>
        </actuator>
        <joint name="rear_right_wheel">
            <hardwareInterface>hardware_interface/VelocityJointInterface</hardwareInterface>
        </joint>
    </transmission>
    <gazebo reference="front_left_wheel_link">
        <material>Gazebo/DarkGrey</material>
        <selfCollide>false</selfCollide>
        <mu1 value="1.0" />
        <mu2 value="1.0" />
        <kp value="10000000.0" />
        <kd value="1" />
        <fdir1 value="1 0 0" />
    </gazebo>
    <gazebo reference="rear_left_wheel_link">
        <material>Gazebo/DarkGrey</material>
        <selfCollide>false</selfCollide>
        <mu1 value="0.05" />
        <mu2 value="0.05" />
        <kp value="10000000.0" />
        <kd value="1" />
        <fdir1 value="1 0 0" />
    </gazebo>
    <gazebo reference="front_right_wheel_link">
        <material>Gazebo/DarkGrey</material>
        <selfCollide>false</selfCollide>
        <mu1 value="1.0" />
        <mu2 value="1.0" />
        <kp value="10000000.0" />
        <kd value="1" />
        <fdir1 value="1 0 0" />
    </gazebo>
    <gazebo reference="rear_right_wheel_link">
        <material>Gazebo/DarkGrey</material>
        <selfCollide>false</selfCollide>
        <mu1 value="0.05" />
        <mu2 value="0.05" />
        <kp value="10000000.0" />
        <kd value="1" />
        <fdir1 value="1 0 0" />
    </gazebo>
    <!-- Spawn Husky chassis -->
    <link name="top_chassis_link">
        <visual>
            <origin rpy="0 0 0" xyz="0 0 0" />
            <geometry>
                <mesh filename="package://husky_ur3_gazebo/meshes/top_chassis.dae" />
            </geometry>
        </visual>
    </link>
    <!-- Attach chassis to the robot -->
    <joint name="top_chassis_joint" type="fixed">
        <parent link="base_link" />
        <child link="top_chassis_link" />
    </joint>
    <!-- Spawn user rails -->
    <link name="user_rail_link">
        <visual>
            <geometry>
                <mesh filename="package://husky_ur3_gazebo/meshes/user_rail.dae" />
            </geometry>
        </visual>
    </link>
    <!-- Attach user rails to base link -->
    <joint name="user_rail" type="fixed">
        <origin rpy="0 0 0" xyz="0.272 0 0.245" />
        <parent link="base_link" />
        <child link="user_rail_link" />
    </joint>
    <!-- Spawn front bumper link -->
    <link name="front_bumper_link">
        <visual>
            <geometry>
                <mesh filename="package://husky_ur3_gazebo/meshes/bumper.dae" />
            </geometry>
        </visual>
    </link>
    <!-- Attach front bumper -->
    <joint name="front_bumper" type="fixed">
        <origin rpy="0 0 0" xyz="0.48 0 0.091" />
        <parent link="base_link" />
        <child link="front_bumper_link" />
    </joint>
    <!-- Spawn rear bumper link -->
    <link name="rear_bumper_link">
        <visual>
            <geometry>
                <mesh filename="package://husky_ur3_gazebo/meshes/bumper.dae" />
            </geometry>
        </visual>
    </link>
    <!-- Attach rear bumper -->
    <joint name="rear_bumper" type="fixed">
        <origin rpy="0 0 3.14159" xyz="-0.48 0 0.091" />
        <parent link="base_link" />
        <child link="rear_bumper_link" />
    </joint>
    <link name="top_plate_link">
        <visual>
            <origin rpy="0 0 0" xyz="0 0 0" />
            <geometry>
                <mesh filename="package://husky_ur3_gazebo/meshes/top_plate.dae" />
            </geometry>
        </visual>
        <collision>
            <origin rpy="0 0 0" xyz="0 0 0" />
            <geometry>
                <mesh filename="package://husky_ur3_gazebo/meshes/top_plate.stl" />
            </geometry>
        </collision>
        <inertial>
            <mass value="0.1" />
            <origin xyz="0 0 0" rpy="0 0 0" />
            <inertia ixx="0.03" iyy="0.03" izz="0.03" ixy="0.0" ixz="0.0" iyz="0.0" />
        </inertial>
    </link>
    <!-- Attach top plate -->
    <joint name="top_plate_joint" type="fixed">
        <parent link="base_link" />
        <child link="top_plate_link" />
        <origin rpy="0 0 0" xyz="0.0812 0 0.245" />
    </joint>
    <!-- Top plate front link -->
    <joint name="top_plate_front_joint" type="fixed">
        <parent link="top_plate_link" />
        <child link="top_plate_front_link" />
        <origin rpy="0 0 0" xyz="0.36367 0 0.00639" />
    </joint>
    <!-- Top plate rear link-->
    <joint name="top_plate_rear_joint" type="fixed">
        <parent link="top_plate_link" />
        <child link="top_plate_rear_link" />
        <origin rpy="0 0 0" xyz="-0.36633 0 0.00639" />
    </joint>
    <link name="top_plate_front_link" />
    <link name="top_plate_rear_link" />
    <!--D435 mount frame -->
    <!--<link name="mount_link">
        <visual>
            <geometry>
                <box size="0.03 0.05 0.01"/>                   
            </geometry>
            <origin xyz = "0.0 0.0 0.0" rpy = "0 ${pi/2} 0"/>
            <material name="Blue">
                <color rgba="0.0 0.0 0.5 1.0"/>
            </material>
        </visual>
        <collision>
            <geometry>
                <box size="0.1054 0.061 0.01"/>                   
            </geometry>
        </collision>    
    </link> 
 
    <joint name="mount_joint" type="fixed">reb
        <origin xyz="0.25 0.0 0.2" rpy="0.0 0.0 0.0"/>
        <parent link="top_plate_link"/>
        <child link="mount_link"/>
    </joint>-->
    <!-- camera body, with origin at bottom screw mount -->
    <joint name="h_camera_joint" type="fixed">
        <origin rpy="0 0 0" xyz="0.4 0.0 0.06" />
        <parent link="top_plate_link" />
        <child link="h_camera_bottom_screw_frame" />
    </joint>
    <link name="h_camera_bottom_screw_frame" />
    <joint name="h_camera_link_joint" type="fixed">
        <origin rpy="0 0 0" xyz="0.010600000000000002 0.0175 0.0125" />
        <parent link="h_camera_bottom_screw_frame" />
        <child link="h_camera_link" />
    </joint>
    <link name="h_camera_link">
        <visual>
            <!-- the mesh origin is at front plate in betw`n the two infrared camera axes -->
            <origin rpy="1.5707963267948966 0 1.5707963267948966" xyz="0.0043 -0.0175 0" />
            <geometry>
                <!-- <box size="${d435_cam_width} ${d435_cam_height} ${d435_cam_depth}"/> -->
                <mesh filename="package://realsense2_description/meshes/d435.dae" />
            </geometry>
            <material name="white">
                <color rgba="0 0 0" />
            </material>
        </visual>
        <collision>
            <origin rpy="0 0 0" xyz="0 -0.0175 0" />
            <geometry>
                <box size="0.02505 0.09 0.025" />
            </geometry>
        </collision>
        <inertial>
            <!-- The following are not reliable values, and should not be used for modeling -->
            <mass value="0.072" />
            <origin xyz="0 0 0" rpy="0 0 0" />
            <inertia ixx="0.003881243" ixy="0.0" ixz="0.0" iyy="0.000498940" iyz="0.0" izz="0.003879257" />
        </inertial>
    </link>
    <!-- camera depth joints and links -->
    <joint name="h_camera_depth_joint" type="fixed">
        <origin rpy="0 0 0" xyz="0 0 0" />
        <parent link="h_camera_link" />
        <child link="h_camera_depth_frame" />
    </joint>
    <link name="h_camera_depth_frame" />
    <joint name="h_camera_depth_optical_joint" type="fixed">
        <origin rpy="-1.5707963267948966 0 -1.5707963267948966" xyz="0 0 0" />
        <parent link="h_camera_depth_frame" />
        <child link="h_camera_depth_optical_frame" />
    </joint>
    <link name="h_camera_depth_optical_frame" />
    <!-- camera left IR joints and links -->
    <joint name="h_camera_infra1_joint" type="fixed">
        <origin rpy="0 0 0" xyz="0 0.0 0" />
        <parent link="h_camera_link" />
        <child link="h_camera_infra1_frame" />
    </joint>
    <link name="h_camera_infra1_frame" />
    <joint name="h_camera_infra1_optical_joint" type="fixed">
        <origin rpy="-1.5707963267948966 0 -1.5707963267948966" xyz="0 0 0" />
        <parent link="h_camera_infra1_frame" />
        <child link="h_camera_infra1_optical_frame" />
    </joint>
    <link name="h_camera_infra1_optical_frame" />
    <!-- camera right IR joints and links -->
    <joint name="h_camera_infra2_joint" type="fixed">
        <origin rpy="0 0 0" xyz="0 -0.05 0" />
        <parent link="h_camera_link" />
        <child link="h_camera_infra2_frame" />
    </joint>
    <link name="h_camera_infra2_frame" />
    <joint name="h_camera_infra2_optical_joint" type="fixed">
        <origin rpy="-1.5707963267948966 0 -1.5707963267948966" xyz="0 0 0" />
        <parent link="h_camera_infra2_frame" />
        <child link="h_camera_infra2_optical_frame" />
    </joint>
    <link name="h_camera_infra2_optical_frame" />
    <!-- camera color joints and links -->
    <joint name="h_camera_color_joint" type="fixed">
        <origin rpy="0 0 0" xyz="0 0.015 0" />
        <parent link="h_camera_link" />
        <child link="h_camera_color_frame" />
    </joint>
    <link name="h_camera_color_frame" />
    <joint name="h_camera_color_optical_joint" type="fixed">
        <origin rpy="-1.5707963267948966 0 -1.5707963267948966" xyz="0 0 0" />
        <parent link="h_camera_color_frame" />
        <child link="h_camera_color_optical_frame" />
    </joint>
    <link name="h_camera_color_optical_frame" />
    <!--
    <xacro:if value="$(arg add_plug)">
      <xacro:usb_plug parent="${name}_link" name="${name}_usb_plug">
        <origin xyz="${d435_cam_mount_from_center_offset - 0.02095} ${-d435_cam_depth_py - 0.0353} 0" rpy="0 0 0"/>
      </xacro:usb_plug>
    </xacro:if>-->
    <gazebo reference="h_camera_link">
        <sensor name="h_camera" type="depth">
            <always_on>1</always_on>
            <visualize>true</visualize>
            <camera>
                <horizontal_fov>1.0471975511965976</horizontal_fov>
                <image>
                    <width>640</width>
                    <height>480</height>
                    <format>R8G8B8</format>
                </image>
                <depth_camera />
                <clip>
                    <near>0.11</near>
                    <far>10</far>
                </clip>
            </camera>
            <plugin filename="libgazebo_ros_openni_kinect.so" name="h_camera_controller">
                <alwaysOn>true</alwaysOn>
                <updateRate>20.0</updateRate>
                <cameraName>h_d435</cameraName>
                <frameName>h_camera_depth_optical_frame</frameName>
                <imageTopicName>rgb/h_image_raw</imageTopicName>
                <depthImageTopicName>depth/h_image_raw</depthImageTopicName>
                <pointCloudTopicName>depth/h_points</pointCloudTopicName>
                <cameraInfoTopicName>rgb/camera_info</cameraInfoTopicName>
                <depthImageCameraInfoTopicName>depth/camera_info</depthImageCameraInfoTopicName>
                <pointCloudCutoff>0.4</pointCloudCutoff>
                <hackBaseline>0.07</hackBaseline>
                <distortionK1>0.0</distortionK1>
                <distortionK2>0.0</distortionK2>
                <distortionK3>0.0</distortionK3>
                <distortionT1>0.0</distortionT1>
                <distortionT2>0.0</distortionT2>
                <CxPrime>0.0</CxPrime>
                <Cx>0.0</Cx>
                <Cy>0.0</Cy>
                <focalLength>0.0</focalLength>
            </plugin>
        </sensor>
    </gazebo>
    <joint name="front_laser_base_joint" type="fixed">
        <origin rpy="0.0 0 0" xyz="0.3206 0.0 -0.000635" />
        <parent link="top_plate_link" />
        <child link="front_laser_base_link" />
    </joint>
    <link name="front_laser_base_link">
        <collision>
            <origin rpy="3.1415926 0 0" xyz="0 0 0" />
            <geometry>
                <mesh filename="package://husky_ur3_gazebo/meshes/sick_tim/sick_tim571.dae" />
            </geometry>
        </collision>
        <visual>
            <origin rpy="3.1415926 0 0" xyz="0 0 0" />
            <geometry>
                <mesh filename="package://husky_ur3_gazebo/meshes/sick_tim/sick_tim571.dae" />
            </geometry>
        </visual>
        <inertial>
            <mass value="1e-5" />
            <origin rpy="3.1415926 0 0" xyz="0 0 0" />
            <inertia ixx="1e-6" ixy="0" ixz="0" iyy="1e-6" iyz="0" izz="1e-6" />
        </inertial>
    </link>
    <joint name="front_laser_joint" type="fixed">
        <origin rpy="0 0 0" xyz="0 0 -0.06246" />
        <parent link="front_laser_base_link" />
        <child link="front_laser_link" />
    </joint>
    <link name="front_laser_link" />
    <gazebo reference="front_laser_link">
        <sensor name="front_laser_sensor" type="ray">
            <pose>0 0 0 0 0 0</pose>
            <visualize>false</visualize>
            <update_rate>15</update_rate>
            <ray>
                <scan>
                    <horizontal>
                        <samples>716</samples>
                        <resolution>1</resolution>
                        <min_angle>-1.57619449019</min_angle>
                        <max_angle>1.57619449019</max_angle>
                    </horizontal>
                </scan>
                <range>
                    <min>0.05</min>
                    <max>25.0</max>
                    <resolution>0.00575</resolution>
                </range>
                <noise>
                    <type>gaussian</type>
                    <mean>0.0</mean>
                    <stddev>0.01</stddev>
                </noise>
            </ray>
            <plugin filename="libgazebo_ros_laser.so" name="front_laser_controller">
                <topicName>/scan</topicName>
                <frameName>/front_laser_link</frameName>
            </plugin>
        </sensor>
    </gazebo>
    <joint name="control_box_ur3_joint" type="fixed">
        <origin rpy="1.570795 0 0" xyz="-0.095 0 0.233" />
        <parent link="top_plate_link" />
        <child link="control_box_ur3_link" />
    </joint>
    <link name="control_box_ur3_link">
        <inertial>
            <mass value="5.0" />
            <origin xyz="0 0 0" rpy="0 0 0" />
            <inertia ixx="0.0" ixy="0.0" ixz="0.0" iyy="0.0" iyz="0.0" izz="0.0" />
        </inertial>
        <visual>
            <origin rpy="0 -1.570795 0 " xyz="0 0 0" />
            <geometry>
                <mesh filename="package://husky_ur3_gazebo/meshes/UR_Contorl_Box.stl" scale="0.001 0.001 0.001" />
            </geometry>
            <material name="gray">
                <color rgba="0.153 0.153 0.153 1" />
            </material>
        </visual>
        <collision>
            <origin rpy="0 0 0 " xyz="-0.1 0 0" />
            <geometry>
                <box size="0.28 0.46 0.37" />
            </geometry>
        </collision>
    </link>
    <gazebo reference="control_box_ur3_link">
        <material>Gazebo/DarkGrey</material>
    </gazebo>
    <gazebo>
        <plugin filename="libgazebo_ros_control.so" name="gazebo_ros_control">
            <robotNamespace>/husky</robotNamespace>
        </plugin>
    </gazebo>
    <gazebo>
        <plugin filename="libhector_gazebo_ros_imu.so" name="imu_controller">
            <robotNamespace>/husky</robotNamespace>
            <updateRate>50.0</updateRate>
            <bodyName>base_link</bodyName>
            <topicName>imu/data</topicName>
            <accelDrift>0.005 0.005 0.005</accelDrift>
            <accelGaussianNoise>0.005 0.005 0.005</accelGaussianNoise>
            <rateDrift>0.005 0.005 0.005</rateDrift>
            <rateGaussianNoise>0.005 0.005 0.005</rateGaussianNoise>
            <headingDrift>0.005</headingDrift>
            <headingGaussianNoise>0.005</headingGaussianNoise>
        </plugin>
    </gazebo>
    <gazebo>
        <plugin filename="libhector_gazebo_ros_gps.so" name="gps_controller">
            <robotNamespace>/husky</robotNamespace>
            <updateRate>40</updateRate>
            <bodyName>base_link</bodyName>
            <frameId>base_link</frameId>
            <topicName>navsat/fix</topicName>
            <velocityTopicName>navsat/vel</velocityTopicName>
            <referenceLatitude>49.9</referenceLatitude>
            <referenceLongitude>8.9</referenceLongitude>
            <referenceHeading>0</referenceHeading>
            <referenceAltitude>0</referenceAltitude>
            <drift>0.0001 0.0001 0.0001</drift>
        </plugin>
    </gazebo>
    <gazebo>
        <!-- -->
        <plugin filename="libgazebo_grasp_fix.so" name="gazebo_grasp_fix">
            <arm>
                <arm_name>h_ur3_gripper</arm_name>
                <palm_link>wrist_3_link</palm_link>
                <!-- <gripper_link>rh_l2</gripper_link>
              <gripper_link>rh_r2</gripper_link> -->
                <gripper_link>rh_p12_rn_l1</gripper_link>
                <gripper_link>rh_p12_rn_l2</gripper_link>
                <gripper_link>rh_p12_rn_r1</gripper_link>
                <gripper_link>rh_p12_rn_r2</gripper_link>
            </arm>
            <forces_angle_tolerance>100</forces_angle_tolerance>
            <update_rate>2</update_rate>
            <grip_count_threshold>1</grip_count_threshold>
            <max_grip_count>2</max_grip_count>
            <release_tolerance>0.005</release_tolerance>
            <disable_collisions_on_attach>true</disable_collisions_on_attach>
            <contact_topic>__default_topic__</contact_topic>
        </plugin>
    </gazebo>
    <!-- This file is a placeholder which is included by default from
       husky.urdf.xacro. If a robot is being customized and requires
       additional URDF, set the HUSKY_URDF_EXTRAS environment variable
       to the full path of the file you would like included. -->
</robot>
<!-- gazebo -->
<!-- <link name="camera_link">
          <visual>
              <origin xyz=" 0 0 0 " rpy="0 0 0" />
              <geometry>
              
                  <sphere radius="0.005" />
                    
              </geometry>
              <material name="red">
                  <color rgba="0 0 0 0.95"/>
              </material>
          </visual>
      </link>

      <joint name="camera_joint" type="fixed">           
          <parent link="ur3_base_link" />
          <child link="camera_link" />
        <origin xyz="-0.3 0.0 2" rpy="0 1.57 0" />

      </joint>
      <gazebo reference="camera_link">
    <sensor name="camera_depth" type="depth">
      <update_rate>20</update_rate>
      <camera>
        <horizontal_fov>1.047198</horizontal_fov>
        <image>
          <width>640</width>
          <height>480</height>
          <format>R8G8B8</format>
        </image>
        <clip>
          <near>0.05</near>
          <far>3</far>
        </clip>
      </camera>
      <plugin name="camera_controller" filename="libgazebo_ros_camera.so">   
        <alwaysOn>true</alwaysOn>
        <updateRate>0.0</updateRate>
        <cameraName>rrbot/camera1</cameraName>
        <imageTopicName>image_raw</imageTopicName>
        <cameraInfoTopicName>camera_info</cameraInfoTopicName>
        <frameName>camera_link</frameName>
        <hackBaseline>0.07</hackBaseline>
        <distortionK1>0.0</distortionK1>
        <distortionK2>0.0</distortionK2>
        <distortionK3>0.0</distortionK3>
        <distortionT1>0.0</distortionT1>
        <distortionT2>0.0</distortionT2>
      </plugin>
    </sensor>
  </gazebo> -->

